Workbook

Sheet Ringkasan PRISMA
A1: Ringkasan angka PRISMA 2020
A2: Kolom hasil hitung dihitung dari lembar kerja. Selisih nol berarti angka sudah sama dengan diagram.
A4: Tahap | B4: Keterangan | C4: Menurut diagram PRISMA | D4: Hasil hitung lembar kerja | E4: Selisih
A5: Identifikasi | B5: Rekaman dari PubMed | C5: 1463 | D5: =COUNTIF('Ekspor gabungan'!$C$5:$C$4743,"PubMed") -> 1463 | E5: =D5-C5 -> 0
A6: Identifikasi | B6: Rekaman dari Scopus | C6: 1148 | D6: =COUNTIF('Ekspor gabungan'!$C$5:$C$4743,"Scopus") -> 1148 | E6: =D6-C6 -> 0
A7: Identifikasi | B7: Rekaman dari Cochrane Library | C7: 231 | D7: =COUNTIF('Ekspor gabungan'!$C$5:$C$4743,"Cochrane Library") -> 231 | E7: =D7-C7 -> 0
A8: Identifikasi | B8: Rekaman dari EBSCOhost | C8: 659 | D8: =COUNTIF('Ekspor gabungan'!$C$5:$C$4743,"EBSCOhost") -> 659 | E8: =D8-C8 -> 0
A9: Identifikasi | B9: Rekaman dari ProQuest | C9: 86 | D9: =COUNTIF('Ekspor gabungan'!$C$5:$C$4743,"ProQuest") -> 86 | E9: =D9-C9 -> 0
A10: Identifikasi | B10: Rekaman dari Europe PMC | C10: 903 | D10: =COUNTIF('Ekspor gabungan'!$C$5:$C$4743,"Europe PMC") -> 903 | E10: =D10-C10 -> 0
A11: Identifikasi | B11: Rekaman dari medRxiv | C11: 249 | D11: =COUNTIF('Ekspor gabungan'!$C$5:$C$4743,"medRxiv") -> 249 | E11: =D11-C11 -> 0
A12: Identifikasi | B12: Total rekaman dari tujuh basis data | C12: 4739 | D12: =COUNTA('Ekspor gabungan'!$B$5:$B$4743) -> 4739 | E12: =D12-C12 -> 0
A13: Identifikasi | B13: Duplikat dihapus | C13: 2262 | D13: =COUNTIF('Ekspor gabungan'!$J$5:$J$4743,"Duplikat") -> 2262 | E13: =D13-C13 -> 0
A14: Skrining | B14: Rekaman diskrining | C14: 2477 | D14: =COUNTA('Skrining judul abstrak'!$A$5:$A$2481) -> 2477 | E14: =D14-C14 -> 0
A15: Skrining | B15: Rekaman dieksklusi pada judul dan abstrak | C15: 2368 | D15: =COUNTIF('Skrining judul abstrak'!$M$5:$M$2481,"Dieksklusi") -> 2368 | E15: =D15-C15 -> 0
A16: Skrining | B16: Laporan dicari naskah lengkapnya | C16: 109 | D16: =COUNTIF('Skrining judul abstrak'!$M$5:$M$2481,"Lanjut ke teks lengkap") -> 109 | E16: =D16-C16 -> 0
A17: Skrining | B17: Laporan tidak berhasil diperoleh | C17: 3 | D17: =COUNTIF('Teks lengkap'!$H$5:$H$113,"Tidak diperoleh") -> 3 | E17: =D17-C17 -> 0
A18: Kelayakan | B18: Laporan dinilai kelayakannya | C18: 106 | D18: =COUNTIF('Teks lengkap'!$G$5:$G$113,"Diperoleh") -> 106 | E18: =D18-C18 -> 0
A19: Kelayakan | B19: Dieksklusi, bukan populasi edema paru kardiogenik akut | C19: 46 | D19: =COUNTIF('Teks lengkap'!$I$5:$I$113,"Bukan populasi edema paru kardiogenik akut") -> 46 | E19: =D19-C19 -> 0
A20: Kelayakan | B20: Dieksklusi, bukan perbandingan NIV dengan oksigenasi konvensional | C20: 16 | D20: =COUNTIF('Teks lengkap'!$I$5:$I$113,"Bukan perbandingan NIV dengan oksigenasi konvensional") -> 16 | E20: =D20-C20 -> 0
A21: Kelayakan | B21: Dieksklusi, mortalitas rumah sakit tidak dilaporkan | C21: 30 | D21: =COUNTIF('Teks lengkap'!$I$5:$I$113,"Mortalitas rumah sakit tidak dilaporkan") -> 30 | E21: =D21-C21 -> 0
A22: Kelayakan | B22: Dieksklusi, laporan ganda atau telah digantikan versi terbaru | C22: 6 | D22: =COUNTIF('Teks lengkap'!$I$5:$I$113,"Laporan ganda atau telah digantikan versi terbaru") -> 6 | E22: =D22-C22 -> 0
A23: Kelayakan | B23: Total dieksklusi pada teks lengkap | C23: 98 | D23: =COUNTIF('Teks lengkap'!$H$5:$H$113,"Dieksklusi") -> 98 | E23: =D23-C23 -> 0
A24: Disertakan | B24: Studi disertakan dari basis data | C24: 8 | D24: =COUNTIF('Teks lengkap'!$H$5:$H$113,"Disertakan") -> 8 | E24: =D24-C24 -> 0
A25: Penelusuran manual | B25: Rekaman dari Jurnal Kardiologi Indonesia (JKI) | C25: 8 | D25: =COUNTIF('Manual searching'!$B$5:$B$58,"Jurnal Kardiologi Indonesia (JKI)") -> 8 | E25: =D25-C25 -> 0
A26: Penelusuran manual | B26: Rekaman dari Jurnal Respirologi Indonesia (JRI) | C26: 2 | D26: =COUNTIF('Manual searching'!$B$5:$B$58,"Jurnal Respirologi Indonesia (JRI)") -> 2 | E26: =D26-C26 -> 0
A27: Penelusuran manual | B27: Rekaman dari JAI (Jurnal Anestesiologi Indonesia) | C27: 6 | D27: =COUNTIF('Manual searching'!$B$5:$B$58,"JAI (Jurnal Anestesiologi Indonesia)") -> 6 | E27: =D27-C27 -> 0
A28: Penelusuran manual | B28: Rekaman dari Majalah Anestesia dan Critical Care (MACC) | C28: 5 | D28: =COUNTIF('Manual searching'!$B$5:$B$58,"Majalah Anestesia dan Critical Care (MACC)") -> 5 | E28: =D28-C28 -> 0
A29: Penelusuran manual | B29: Rekaman dari Solo Journal of Anesthesi, Pain and Critical Care (SOJA) | C29: 1 | D29: =COUNTIF('Manual searching'!$B$5:$B$58,"Solo Journal of Anesthesi, Pain and Critical Care (SOJA)") -> 1 | E29: =D29-C29 -> 0
A30: Penelusuran manual | B30: Rekaman dari Current Internal Medicine Research and Practice Surabaya Journal (CIMRJ) | C30: 1 | D30: =COUNTIF('Manual searching'!$B$5:$B$58,"Current Internal Medicine Research and Practice Surabaya Journal (CIMRJ)") -> 1 | E30: =D30-C30 -> 0
A31: Penelusuran manual | B31: Rekaman dari Cardiovascular and Cardiometabolic Journal (CCJ) | C31: 2 | D31: =COUNTIF('Manual searching'!$B$5:$B$58,"Cardiovascular and Cardiometabolic Journal (CCJ)") -> 2 | E31: =D31-C31 -> 0
A32: Penelusuran manual | B32: Rekaman dari Majalah Kedokteran Indonesia (JIMA) | C32: 1 | D32: =COUNTIF('Manual searching'!$B$5:$B$58,"Majalah Kedokteran Indonesia (JIMA)") -> 1 | E32: =D32-C32 -> 0
A33: Penelusuran manual | B33: Rekaman dari eJournal Kedokteran Indonesia (eJKI) | C33: 0 | D33: =COUNTIF('Manual searching'!$B$5:$B$58,"eJournal Kedokteran Indonesia (eJKI)") -> 0 | E33: =D33-C33 -> 0
A34: Penelusuran manual | B34: Rekaman dari Indonesian Journal of Chest (IJC) | C34: 1 | D34: =COUNTIF('Manual searching'!$B$5:$B$58,"Indonesian Journal of Chest (IJC)") -> 1 | E34: =D34-C34 -> 0
A35: Penelusuran manual | B35: Rekaman dari Jurnal Gawat Darurat (JGD) | C35: 0 | D35: =COUNTIF('Manual searching'!$B$5:$B$58,"Jurnal Gawat Darurat (JGD)") -> 0 | E35: =D35-C35 -> 0
A36: Penelusuran manual | B36: Rekaman dari Jurnal Penyakit Dalam Indonesia (JPDI) | C36: 27 | D36: =COUNTIF('Manual searching'!$B$5:$B$58,"Jurnal Penyakit Dalam Indonesia (JPDI)") -> 27 | E36: =D36-C36 -> 0
A37: Penelusuran manual | B37: Total rekaman penelusuran manual | C37: 54 | D37: =COUNTA('Manual searching'!$A$5:$A$58) -> 54 | E37: =D37-C37 -> 0
A38: Penelusuran manual | B38: Laporan dicari | C38: 54 | D38: =COUNTIF('Manual searching'!$J$5:$J$58,"Ya") -> 54 | E38: =D38-C38 -> 0
A39: Penelusuran manual | B39: Laporan dinilai kelayakannya | C39: 54 | D39: =COUNTIF('Manual searching'!$K$5:$K$58,"Ya") -> 54 | E39: =D39-C39 -> 0
A40: Penelusuran manual | B40: Dieksklusi, bukan populasi edema paru kardiogenik akut | C40: 29 | D40: =COUNTIF('Manual searching'!$M$5:$M$58,"Bukan populasi edema paru kardiogenik akut") -> 29 | E40: =D40-C40 -> 0
A41: Penelusuran manual | B41: Dieksklusi, tidak memuat intervensi NIV, CPAP, maupun BiPAP | C41: 25 | D41: =COUNTIF('Manual searching'!$M$5:$M$58,"Tidak memuat intervensi NIV, CPAP, maupun BiPAP") -> 25 | E41: =D41-C41 -> 0
...

Sheet Ekspor gabungan
A1: Ekspor gabungan dari tujuh basis data (n = 4.739)
A2: Pencarian 24 Oktober 2026 pukul 21.00 WIB. Rekaman yang sudah muncul pada basis data sebelumnya ditandai Duplikat.
A4: No | B4: ID rekaman | C4: Basis data | D4: DOI | E4: Penulis | F4: Judul | G4: Tahun | H4: Jurnal | I4: Abstrak | J4: Status | K4: Verifikasi Crossref
A5: 1 | B5: S0052 | C5: PubMed | D5: 10.1016/s1388-9842(99)00008-2 | E5: Richardson M, Cockburn N, Cleland JGF | F5: Update of Recent Clinical Trials in Heart Failure and Myocardial Infarction | G5: 1999 | H5: European Journal of Heart Failure | I5: There are currently many on-going clinical trials assessing therapies for the treatment of patients with heart failure. The purpose of this series of papers is to present concise summaries of current randomised trials in the field of heart failure and myocardial infarction (MI). Data from large double-blind, placebo-controlled trials, which are on-going or have only recently been published, are given in a format allowing easy comparison. Where appropriate, data from smaller studies are included. Major studies which are examined in this issue include CIBIS II, MERIT-HF, RESOLVD, SPICE, VEST, MACH-1, ATLAS, RALES, CIDS and CASH. These trials assess the efficacy and safety of beta-blocker, angiotensin-II-receptor blocker, positive inotropic agent, calcium antagonist, angiotensin-converting enzyme (ACE) inhibitor, aldosterone receptor blocker, and antiarrhythmic interventions in the treatment of heart failure. The presentation of data from these on-going trials should allow an up-to-date assessment, by physicians, of the most appropriate and effective treatment for patients with heart failure. It is evident that some therapies may play no further role in the treatment of heart failure, due to the increased risk of mortality associated with their administration, whilst others may convey significant benefits. | J5: Asli | K5: Terverifikasi
A6: 2 | B6: S0610 | C6: PubMed | D6: 10.1164/ajrccm.153.3.8630538 | E6: Patrick W, Webster K, Ludwig L, Roberts D, Wiebe P, Younes M | F6: Noninvasive Positive-Pressure Ventilation in Acute Respiratory Distress Without Prior Chronic Respiratory Failure | G6: 1996 | H6: American journal of respiratory and critical care medicine | I6: We evaluated the efficacy of noninvasive mechanical ventilation (NIMV) in alleviating distress and avoiding intubation in patients with de novo acute respiratory failure complicating primary medical disorders. Eleven consecutive patients with severe respiratory distress were entered. In all patients a decision to intubate on an urgent basis had been made, but NIMV could be initiated within minutes. The patients suffered from acute pulmonary edema (five), sepsis/ARDS (two), status asthmaticus (two), and severe pneumonia (two). Dyspnea score (max=10) was (+/- SD) 8.4 +.- 1.6, scale for accessory muscle use (max=5) was 4.2 +/- 0.7, and respiratory rate was 37.6 +/- 3.8 min -1. Pa CO2, pH, and base excess (BE) were 48 +/- 18 mm Hg, 7.27 +/- 0.13, and -5.5 +/- 7.4, respectively, with five patients showing severe metabolic acidosis (BE &amp;lt; - 10). NIMV was applied using proportional assist ventilation. There were three early failures. These included the two patients with sepsis/ARDS who did not tolerate the mask. One patient failed because Pa CO2 and pH deteriorated despite subjective improvement. The remaining eight patients demonstrated progressive improvement, and none required intubation. The duration of NIMV was 3 h to 2 d. We conclude that when NIMV is made available on a "few minutes" basis, selected patients with severe de novo respiratory distress/failure caused by reversible medical disorders, who would otherwise have been intubated, can be given substantial relief and be spared intubation. | J6: Asli | K6: Terverifikasi
A7: 3 | B7: S1484 | C7: PubMed | D7: 10.1016/s1388-9842(00)00058-1 | E7: Kiilavuori K, Näveri H, Salmi T, Härkönen M | F7: The Effect of Physical Training on Skeletal Muscle in Patients with Chronic Heart Failure | G7: 2000 | H7: European Journal of Heart Failure | I7: The improvement of exercise capacity in patients with chronic heart failure (CHF) by physical training has been connected with reversal of the abnormalities in muscle fiber distribution and with the reduced activity of the enzymes of oxidative metabolism in skeletal muscle. However, the change in fiber type distribution induced by training is controversial and in previous studies the activities of the rate-limiting enzymes of the metabolic pathways have not been measured. To examine the effect of dynamic training on percentage distribution of muscle fibers, on activities of the rate-limiting enzymes of the metabolic pathways and on electrophysiology in skeletal muscle. A total of 27 patients with stable CHF (NYHA class II–III) were randomized to a training (N=12) or a control (N=15) group. The training group exercised on a bicycle ergometer for 30 min three times a week for 3 months using a load corresponding to 50–60% of their peak oxygen consumption. This was followed by a 3-month training period at home according to personal instructions. The control group did not change its physical activities. We studied muscle histology and measured the activities of the rate-limiting enzymes of anaerobic glycolysis (phosphofructokinase, PFK), glycogenolysis (phosphorylase), citric acid cycle (α-ketoglurate dehydrogenase, KGDH) and fatty acid oxidation (carnitinepalmitoyl transferase I and II, CPT I and II) from biopsies of the vastus lateralis muscle at baseline and after 3 and 6 months. Muscle strength and strength endurance with surface EMG and macro EMG of the right knee extensors were also determined. Exercise capacity, particularly submaximal, improved in the training group. The activity of PFK rose significantly but that of the other enzymes did not when compared with the change in the controls. Training had no effect on the percentage distribution of slow-twitch and fast-twitch muscle fibers or on capillary density around these fibers in skeletal muscle. Maximum voluntary force, strength endurance and the function of motor units remained unaffected. Dynamic training results in improved exercise endurance in CHF. In skeletal muscle, the capacity of anaerobic glycolysis is increased but that of the citric acid cycle and fatty acid oxidation is not. Furthermore, the improvement in exercise endurance seems to be independent of changes in the percentage distribution of muscle fibers, capillarity or electrophysiological factors. | J7: Asli | K7: Terverifikasi
A8: 4 | B8: S1264 | C8: PubMed | D8: 10.1136/heart.87.3.229 | E8: Struthers AD, Donnan PT, Lindsay P, McNaughton D, Broomhall J, MacDonald TM | F8: Effect of allopurinol on mortality and hospitalisations in chronic heart failure: a retrospective cohort study | G8: 2002 | H8: Heart | I8: Objective: To examine whether allopurinol is associated with any alteration in mortality and hospitalisations in patients with chronic heart failure (CHF). This hypothesis is based on previous data that a high urate concentration is independently associated with mortality with a risk ratio of 4.23 in CHF. Design: Retrospective cohort study. Setting: Medicines Monitoring Unit, Ninewells Hospital, Dundee, UK. Patients: 1760 CHF patients divided into four groups: those on no allopurinol, those on long term low dose allopurinol, those on short term low dose allopurinol, and those on long term high dose allopurinol. Main outcome measures: Total mortality, cardiovascular mortality, cardiovascular hospitalisations, cardiovascular mortality or hospitalisations. Results: Long term low dose allopurinol was associated with a significant worsening in mortality over those who never received allopurinol (relative risk 2.04, 95% confidence interval (CI) 1.48 to 2.81). This may be because low dose allopurinol is insufficient to negate the adverse effect of a high urate concentration. However, long term high dose (≥ 300 mg/day) allopurinol was associated with a significantly better mortality than longstanding low dose allopurinol (relative risk 0.59, 95% CI 0.37 to 0.95). This may mean that high dose allopurinol can fully negate the adverse effect of urate and return the mortality to normal. Conclusions: Long term high dose allopurinol may be associated with a better mortality than long term low dose allopurinol in patients with CHF because of a dose related beneficial effect of allopurinol against the well described adverse effect of urate. Further work is required to substantiate or refute this finding. | J8: Asli | K8: Terverifikasi
A9: 5 | B9: S1896 | C9: PubMed | D9: 10.1310/hpj4804-270 | E9: Mancano MA | F9: Statin-Induced Lung Injury; Colchicine-Induced Rhabdomyolysis Caused by Interaction with Clarithromycin; Disulfiram Ethanol Reaction Mimicking Anaphylactic, Cardiogenic, and Septic Shock; Weight Gain with Abdominal Enlargement in a Patient Receiving Tocilizumab; Nilotinib-Associated Acute Pancreatitis | G9: 2013 | H9: Hospital Pharmacy | I9: The purpose of this feature is to heighten awareness of specific adverse drug reactions (ADRs), discuss methods of prevention, and promote reporting of ADRs to the US Food and Drug Administration's (FDA's) MedWatch program (800-FDA-1088). If you have reported an interesting, preventable ADR to MedWatch, please consider sharing the account with our readers. | J9: Asli | K9: Terverifikasi
A10: 6 | B10: S2347 | C10: PubMed | D10: 10.1002/14651858.cd005351.pub3 | E10: Vital FM, Ladeira MT, Atallah ÁN | F10: Non-invasive positive pressure ventilation (CPAP or bilevel NPPV) for cardiogenic pulmonary oedema | G10: 2013 | H10: Cochrane Database of Systematic Reviews | I10: This is an update of a systematic review previously published in 2008 about non-invasive positive pressure ventilation (NPPV). NPPV has been widely used to alleviate signs and symptoms of respiratory distress due to cardiogenic pulmonary oedema. NPPV prevents alveolar collapse and helps redistribute intra-alveolar fluid, improving pulmonary compliance and reducing the pressure of breathing. To determine the effectiveness and safety of NPPV in the treatment of adult patients with cardiogenic pulmonary oedema in its acute stage. We searched the following databases on 20 April 2011: CENTRAL and DARE, (The Cochrane Library, Issue 2 of 4, 2011); MEDLINE (Ovid, 1950 to April 2011); EMBASE (Ovid, 1980 to April 2011); CINAHL (1982 to April 2011); and LILACS (1982 to April 2011). We also reviewed reference lists of included studies and contacted experts and equipment manufacturers. We did not apply language restrictions. We selected blinded or unblinded randomised or quasi-randomised clinical trials, reporting on adult patients with acute or acute-on-chronic cardiogenic pulmonary oedema and where NPPV (continuous positive airway pressure (CPAP) or bilevel NPPV) plus standard medical care was compared with standard medical care alone. Two authors independently selected articles and abstracted data using a standardised data collection form. We evaluated study quality with emphasis on allocation concealment, sequence generation allocation, losses to follow-up, outcome assessors, selective outcome reporting and adherence to the intention-to-treat principle. We included 32 studies (2916 participants), of generally low or uncertain risk of bias. Compared with standard medical care, NPPV significantly reduced hospital mortality (RR 0.66, 95% CI 0.48 to 0.89) and endotracheal intubation (RR 0.52, 95% CI 0.36 to 0.75). We found no difference in hospital length of stay with NPPV; however, intensive care unit stay was reduced by 1 day (WMD -0.89 days, 95% CI -1.33 to -0.45). Compared with standard medical care, we did not observe significant increases in the incidence of acute myocardial infarction with NPPV during its application (RR 1.24, 95% CI 0.79 to 1.95) or after (RR 0.70, 95% CI 0.11 to 4.26). We identified fewer adverse events with NPPV use (in particular progressive respiratory distress and neurological failure (coma)) when compared with standard medical care. NPPV in addition to standard medical care is an effective and safe intervention for the treatment of adult patients with acute cardiogenic pulmonary oedema. The evidence to date on the potential benefit of NPPV in reducing mortality is entirely derived from small-trials and further large-scale trials are needed. | J10: Asli | K10: Terverifikasi
A11: 7 | B11: S0689 | C11: PubMed | D11: 10.1016/s2213-2600(16)30093-5 | E11: Frat JP, Ragot S, Girault C, Perbet S, Prat G, Boulain T, Demoule A, Ricard JD, Coudroy R, Robert R, Mercat A, Brochard L, Thille AW | F11: Effect of non-invasive oxygenation strategies in immunocompromised patients with severe acute respiratory failure: a post-hoc analysis of a randomised trial | G11: 2016 | H11: The Lancet Respiratory Medicine | I11: The use of non-invasive ventilation is controversial in immunocompromised patients with acute respiratory failure, whereas the use of high-flow nasal cannula oxygen therapy is growing as an alternative to standard oxygen. We aimed to compare outcomes of immunocompromised patients with acute respiratory failure treated with standard oxygen with those treated with high-flow nasal cannula oxygen alone or high-flow nasal cannula oxygen associated with non-invasive ventilation. We did a post-hoc subgroup analysis in a subset of immunocompromised patients with non-hypercapnic acute respiratory failure from a multicentre, randomised, controlled trial. In the trial, patients from 23 intensive care units in France and Belgium were randomly assigned (1:1:1) to receive either standard oxygen, high-flow nasal cannula alone, or non-invasive ventilation interspaced with high-flow nasal cannula between non-invasive ventilation sessions (non-invasive ventilation group). Patients with profound neutropenia, acute-on-chronic respiratory failure, cardiogenic pulmonary oedema, shock, or altered consciousness were excluded. The primary outcome was the proportion of patients who required endotracheal intubation within 28 days after randomisation. Of the 82 immunocompromised patients, 30 were treated with standard oxygen, 26 with high-flow nasal cannula alone, and 26 with non-invasive ventilation plus interspaced high-flow nasal cannula. 8 (31%) of 26 patients treated with high-flow nasal cannula alone, 13 (43%) of 30 patients treated with standard oxygen, and 17 (65%) of 26 patients treated with non-invasive ventilation required intubation at 28 days (p=0·04). Odds ratios (ORs) for intubation were higher in patients treated with non-invasive ventilation than in those treated with high-flow nasal cannula: OR 4·25 (95% CI 1·33-13·56). ORs were not significantly different between patients treated with high-flow nasal cannula alone and standard oxygen: OR 1·72 (0·57-5·18). After multivariable logistic regression, the two factors independently associated with endotracheal intubation and mortality were age and use of non-invasive ventilation as first-line therapy. Non-invasive ventilation might be associated with an increased risk of intubation and mortality and should be used cautiously in immunocompromised patients with acute hypoxaemic respiratory failure. French Ministry of Health, the French societies of intensive care (Société de Réanimation de Langue Française, SRLF) and pneumology (Société de Pneumologie de Langue Française, SPLF), La Mutuelle de Poitiers, AADAIRC (Association pour l'Assistance à Domicile Aux Insuffisants Respiratoires Chroniques), and Fisher&Paykel Healthcare. | J11: Asli | K11: Terverifikasi
A12: 8 | B12: S1865 | C12: PubMed | D12: 10.1152/jappl.1989.66.1.288 | E12: Barrowcliffe MP, Zanelli GD, Jones JG | F12: Pulmonary clearance of radiotracers after positive end-expiratory pressure or acute lung injury | G12: 1989 | H12: Journal of Applied Physiology | I12: In anesthetized rabbits we measured clearance from lung to blood of eight aerosolized technetium-99m-labeled compounds: diethylenetriaminepentaacetate (99mTc-DTPA); cytochrome c; myoglobin; a myoglobin polymer; albumin; and anionic, cationic, and neutral dextrans of equivalent molecular size. We investigated the effect of applying positive end-expiratory pressure (PEEP) and, on a subsequent occasion, of injecting oleic acid intravenously to produce acute lung injury on the pulmonary clearance rate. Base-line clearance rates were monoexponential and varied with the molecular weights of the radiotracers. For each tracer the rate of clearance was increased a similar degree by either PEEP or oleic acid. However, with PEEP, clearance remained monoexponential, whereas after oleic acid, smaller molecular-weight radiotracers had multiexponential clearance curves. This suggests that after oleic acid the alveolar epithelium breaks down in a nonuniform fashion. We conclude that differentiation of the effect of PEEP from that of severe lung injury caused by oleic acid is not readily accomplished by either increasing the size of the tracer molecule or by varying the molecular charge. | J12: Asli | K12: Terverifikasi
A13: 9 | B13: S1472 | C13: PubMed | D13: 10.1111/eci.12908 | E13: Baratta F, Pastori D, Fabiani M, Fabiani V, Ceci F, Lillo R, Lolli V, Brunori M, Pannitteri G, Cravotto E, De Vito C, Angelico F, Del Ben M | F13: Severity of OSAS, CPAP and cardiovascular events: A follow‐up study | G13: 2018 | H13: European Journal of Clinical Investigation | I13: Previous studies suggested obstructive sleep apnoea syndrome ( OSAS ) as a major risk factor for incident cardiovascular events. However, the relationship between OSAS severity, the use of continuous positive airway pressure ( CPAP ) treatment and the development of cardiovascular disease is still matter of debate. The aim was to test the association between OSAS and cardiovascular events in patients with concomitant cardio‐metabolic diseases and the potential impact of CPAP therapy on cardiovascular outcomes. Prospective observational cohort study of consecutive outpatients with suspected metabolic disorders who had complete clinical and biochemical workup including polysomnography because of heavy snoring and possible OSAS . The primary endpoint was a composite of major adverse cardiovascular and cerebrovascular events ( MACCE ). Median follow‐up was 81.3 months, including 434 patients (2701.2 person/years); 83 had a primary snoring, 84 had mild, 93 moderate and 174 severe OSAS , respectively. The incidence of MACCE was 0.8% per year (95% confidence interval [ CI ] 0.2‐2.1) in primary snorers and 2.1% per year (95% CI 1.5‐2.8) for those with OSAS . A positive association was observed between event‐free survival and OSAS severity (log‐rank test; P = .041). A multivariable Cox regression analysis showed obesity ( HR = 8.011, 95% CI 1.071‐59.922, P = .043), moderate OSAS (vs non‐ OSAS HR = 3.853, 95% CI 1.069‐13.879, P = .039) and severe OSAS (vs non‐ OSAS HR = 3.540, 95% CI 1.026‐12.217, P = .045) as predictors of MACCE . No significant association was observed between CPAP treatment and MACCE (log‐rank test; P = .227). Our findings support the role of moderate/severe OSAS as a risk factor for incident MACCE . CPAP treatment was not associated with a lower rate of MACCE . | J13: Asli | K13: Terverifikasi
A14: 10 | B14: S1797 | C14: PubMed | D14: 10.1097/00000542-200204000-00007 | E14: Drummond GB, Stedul K, Kingshott R, Rees K, Nimmo AF, Wraith P, Douglas NJ | F14: Automatic CPAP Compared with Conventional Treatment for Episodic Hypoxemia and Sleep Disturbance after Major Abdominal Surgery | G14: 2002 | H14: Anesthesiology | I14: After major surgery, analgesia with opioids can cause obstructive apnea and intermittent hypoxemia, probably from loss of upper airway control. Since this resembles the obstructive sleep apnea syndrome, we tested the possibility that nasal continuous positive airway pressure (nCPAP) would reduce episodes of reduced oxygen saturation and sleep disruption. Because oxygen therapy is frequent after surgery, we also assessed the effect of oxygen on sleep disruption. We recruited 48 patients about to have major abdominal surgery. We present data for 34 patients: 27 who received patient-controlled intravenous morphine and 7 who received epidural opioid. Treatment was randomized to either nCPAP or conventional therapy with an oxygen mask. Alternate periods of administration of air and 35% oxygen were used in both groups. If the oxygen saturation as measured by pulse oximetry was consistently &lt;90% on air, the patient was withdrawn from the study. We measured sleep, arousals, oxygenation, episodes of desaturation, and disturbances of respiration. Values are given as median and quartiles. The median proportion of time awake was 65% (45-79%) among control patients and 74% (55-87%) among those undergoing nCPAP. Oxygen administration did not affect the sleep pattern. The median frequency of arousals per hour of sleep was very similar in each group: during air breathing from nCPAP, 125 (76-187), and during air breathing by mask, 116 (84-187). Oxygen therapy had no effect. Oxygenation and hypoxemic events were not improved by nCPAP. Oxygen therapy improved oxygenation and reduced but did not eliminate episodes of desaturation. Nasal CPAP does not improve sleep and oxygenation or reduce hypoxemic events in the first night after major abdominal surgery. | J14: Asli | K14: Terverifikasi
A15: 11 | B15: S1469 | C15: PubMed | D15: 10.1016/s0140-6736(00)03492-9 | E15: Masip J, Betbesé AJ, Páez J, Vecilla F, Cañizares R, Padró J, Paz MA, Otero Jd, Ballús J | F15: Non-invasive pressure support ventilation versus conventional oxygen therapy in acute cardiogenic pulmonary oedema: a randomised trial | G15: 2000 | H15: The Lancet | I15: Non-invasive pressure support ventilation (NIPSV) is an effective treatment for acute respiratory failure in patients with chronic obstructive pulmonary disease. We assessed the efficacy of this therapy in acute cardiogenic pulmonary oedema in a randomised comparison with conventional oxygen therapy. 40 patients were randomly assigned conventional oxygen therapy or NIPSV supplied by a standard ventilator through a face mask, with adjustment of tidal volume and pressure support in addition to a positive end-expiratory pressure of 5 cm water. Physiological measurements were obtained in the first 2 h and at 3 h, 4 h, and 10 h. The main endpoints were intubation rate and resolution time. Analyses were by intention to treat. Three patients were withdrawn on the basis of clinical and chest radiography results. Endotracheal intubation was required in one (5%) of 19 patients assigned NIPSV and in six (33%) of 18 assigned conventional oxygen therapy (p=0.037). Resolution time (defined as a clinical improvement with oxygen saturation of 96% or more and respiratory rate less than 30 breaths/min) was significantly shorter in the NIPSV group (median 30 [IQR 15-53] vs 105 [50-230] min, p=0.002). NIPSV led to a rapid improvement in oxygenation in the first 2 h. There were no differences in hospital length of stay or mortality. In this study of acute cardiogenic pulmonary oedema, NIPSV was superior to conventional oxygen therapy. Further studies should compare NIPSV with continuous positive airway pressure. | J15: Asli | K15: Terverifikasi
A16: 12 | B16: S2409 | C16: PubMed | D16: 10.1161/01.cir.0000022692.49934.e3 | E16: Al-Khatib SM, Granger CB, Huang Y, Lee KL, Califf RM, Simoons ML, Armstrong PW, Van de Werf F, White HD, Simes RJ, Moliterno DJ, Topol EJ, Harrington RA | F16: Sustained Ventricular Arrhythmias Among Patients With Acute Coronary Syndromes With No ST-Segment Elevation | G16: 2002 | H16: Circulation | I16: Background — The prognosis of ventricular arrhythmias among patients with non–ST-elevation acute coronary syndromes is unknown. We studied the incidence, predictors, and outcomes of sustained ventricular arrhythmias in 4 large randomized trials of such patients. Methods and Results — We pooled the datasets of the Global Use of Streptokinase and tPA for Occluded Arteries (GUSTO)-IIb, Platelet Glycoprotein IIb/IIIa in Unstable Angina: Receptor Suppression Using Integrilin Therapy (PURSUIT), Platelet IIb/IIIa Antagonism for the Reduction of Acute Coronary Syndrome Events in a Global Organization Network (PARAGON)-A, and PARAGON-B trials (n=26 416). We identified independent predictors of ventricular fibrillation (VF) and ventricular tachycardia (VT) and compared the 30-day and 6-month mortality rates of patients who did (n=552) and did not (n=25 864) develop these arrhythmias during the index hospitalization. Independent predictors of in-hospital VF included prior hypertension, chronic obstructive pulmonary disease, prior myocardial infarction, and ST-segment changes at presentation. Except for hypertension, these variables also independently predicted in-hospital VT. In Cox proportional-hazards modeling, in-hospital VF and VT were independently associated with 30-day mortality (hazard ratio [HR], 23.2 [95% CI, 18.1 to 29.8] for VF and HR, 7.6 [95% CI, 5.5 to 10.4] for VT) and 6-month mortality (HR, 14.8 [95% CI, 12.1 to 18.3] for VF and HR, 5.0 [95% CI, 3.8 to 6.5] for VT). These differences remained significant after excluding patients with heart failure or cardiogenic shock and those who died &lt;24 hours after enrollment. Conclusions — Despite the use of effective therapies for non–ST-elevation acute coronary syndromes, ventricular arrhythmias in this setting are associated with increased 30-day and 6-month mortality. More effective therapies are needed to improve the survival of patients with these arrhythmias. | J16: Asli | K16: Terverifikasi
... A111: 107 | B111: S1206 | C111: PubMed | D111: 10.5005/jp-journals-10071-24335 | E111: Karim HMR, Esquinas AM | F111: Ketamine Sedation for Noninvasive Ventilation in Distressed Elderly Patients with Acute Decompensated Heart Failure: Is it Safe? | G111: 2022 | H111: Indian Journal of Critical Care Medicine | I111: How to cite this article: Karim HMR, Esquinas AM. Ketamine Sedation for Noninvasive Ventilation in Distressed Elderly Patients with Acute Decompensated Heart Failure: Is it Safe? Indian J Crit Care Med 2022;26(10):1161. | J111: Asli | K111: Terverifikasi
A112: 108 | B112: S2250 | C112: PubMed | D112: 10.21203/rs.3.rs-30079/v1 | E112: Fabre M, Fehlmann CA, Gartner B, Zimmermann CG, Rey F, Sarasin F, Suppan L | F112: Association between Prehospital Arterial Hypercapnia in Acute Heart Failure and Admission to Acute Care Units: a Retrospective Cohort Study | G112: 2020 | I112: Abstract Background Acute Heart Failure (AHF) is a common condition that often manifests by acute respiratory distress and requires urgent medical evaluation and treatment. Arterial hypercapnia is common in AHF. It has been associated with a higher rate of intubation and non-invasive ventilation in the Emergency Room (ER), but its prognostic value has never been studied in the prehospital setting. Methods A retrospective study was performed on the charts of all patients taken care of by a physician-staffed prehospital mobile unit between June 2016 and September 2019 in Geneva. After approval by the ethics committee, charts were screened to identify all adult patients with a diagnosis of AHF. The main predictor was prehospital hypercapnia. The primary outcome was admission rate in an acute care unit (ACU, composite of intensive care or high-dependency units). Secondary outcomes were ER length of stay (LOS), orientation from ER (intensive care unit, high-dependency unit, general ward, discharge home), intubation rate at 24 hours, hospital LOS and hospital mortality. Results A total of 104 patients with a diagnosis of AHF were included. Hypercapnia was found in 59 (57%) patients and vital signs were more severely altered in this group. The overall ACU admission rate was 47%, with a statistically significant difference between hypercapnic and non-hypercapnic patients (58% vs 33% respectively, p = 0.014). ER LOS was shorter in hypercapnic patients (5.5 hours vs 8.9 hours, p = 0.008). Conclusions There is a significant association between prehospital arterial hypercapnia and acute care unit admission in AHF patients. | J112: Asli | K112: Terverifikasi
A113: 109 | B113: S0555 | C113: PubMed | D113: 10.1177/0885066616636021 | E113: Alaya S, Mofredj A, Tassaioust K, Bahloul H, Mrabet A | F113: Acute Parotitis as a Complication of Noninvasive Ventilation | G113: 2016 | H113: Journal of Intensive Care Medicine | I113: Several conditions, including oropharyngeal dryness, pressure sores, ocular irritation, epistaxis, or gastric distension, have been described during noninvasive ventilation (NIV). Although this technique has been widely used in intensive care units and emergency wards, acute swelling of the parotid gland remains a scarcely reported complication. We describe herein the case of an 82-year-old man who developed unilateral parotitis during prolonged NIV for acute heart failure. Intravenous antibiotics, corticosteroids, and adjusting the mask laces’ position allowed rapid resolution of clinical symptoms. | J113: Asli | K113: Terverifikasi
A114: 110 | B114: S2470 | C114: PubMed | D114: 10.1007/s00134-006-0324-1 | E114: Demoule A, Girou E, Richard JC, Taille S, Brochard L | F114: Benefits and risks of success or failure of noninvasive ventilation | G114: 2006 | H114: Intensive Care Medicine | I114: Noninvasive ventilation (NIV) fails more frequently for de novo acute respiratory failure (de novo) than for cardiogenic pulmonary edema (CPE) or acute-on-chronic respiratory failure (AOC). The impact of NIV failure and success was compared between de novo and CPE or AOC after adjustment for disease severity. Patients requiring ventilatory support were enrolled in a prospective survey in 70 French ICUs. Of 1076 patients requiring ventilatory support, 524 were eligible, including 299 de novo (NIV use, 30%) and 225 CPE-AOC (NIV use, 55%). Independent risk factors associated with mortality and length of stay were identified by logistic regression analysis. The adjusted outcome of NIV success or failure was compared to that with endotracheal intubation without NIV. NIV success was independently associated with survival in both de novo, adjusted OR 0.05 (95% CI 0.01-0.42), and CPE-AOC OR 0.03 (CI 0.01-0.24). NIV failure was associated with ICU mortality in the de novo group (OR 3.24, CI 1.61-6.53) but not in the CPE-AOC group. Nosocomial pneumonia was less common in patients successful with NIV. NIV failure was associated with a longer ICU stay in CPE-AOC only. The overall use of NIV was independently associated with a better outcome only in CPE-AOC patients (OR 0.33, CI 0.15-0.73). The effect of NIV differs between de novo and CPE-AOC patients because NIV failure is associated with increased mortality for de novo patients. This finding should raise a note of caution when applying NIV in this indication. | J114: Asli | K114: Terverifikasi
A115: 111 | B115: S0734 | C115: PubMed | D115: 10.1097/00003246-198202000-00001 | E115: NIKKI P, RÄSÄNEN J, TAHVANAINEN J, MÄKELÄINEN A | F115: Ventilatory pattern in respiratory failure arising from acute myocardial infarction. I. Respiratory and hemodynamic effects of IMV4 vs IPPV12 and PEEP0 vs PEEP10 | G115: 1982 | H115: Critical Care Medicine | I115: Positive end-expiratory pressure of 10 cm H2O (PEEP10) was compared with zero-end-expiratory pressure (PEEP0), intermittent mandatory ventilation (IMV), 4/min, with intermittent positive pressure ventilation (IPPV), 12/min, in 9 patients with pulmonary edema due to acute myocardial infarction (AMI). Systemic and pulmonary arterial pressures, pulmonary capillary wedge pressure (PCWP) and CVP, cardiac output (CO) and blood gases were measured during these four experimental interventions, and related parameters calculated. PaCO2 was 39.3 +/- 0.9 torr during IMV4 and 36.2 +/- 1.3 torr during IPPV12, and PCWP remained between 20-30 mm Hg throughout the study. The ventilatory pattern was changed at random order with the patient serving as his own control. Both PaO2 and PaO2/F102 and VO2 increased while venous admixture (Qsp/Qt) decreased with PEEP10. Cardiac and stroke indices (CI, SI) and oxygen delivery were lower with IPPV12 than they were with IMV4. Both left and right ventricular stroke work (LVSW, RVSW) were higher on IMV4. A moderate PEEP level (up to 10 cm H2O) seems beneficial in post-AMI pulmonary edema and has no significant hemodynamic side effects. The results indicate that of the four alternatives studied, IMV4 with PEEP10 is a ventilatory pattern of choice in the respiratory management of these patients, but each individual patient may require precise titration of each modality to achieve the optimal result. | J115: Asli | K115: Terverifikasi
A116: 112 | B116: S1036 | C116: PubMed | D116: 10.1097/00003246-198707000-00010 | E116: HAYEK Z, RYAN CA, EYAL F, JONES R, ARMENGOL J, KING EG, FINER NN | F116: Comparison of high-frequency chest wall compression with conventional mechanical ventilation in cats | G116: 1987 | H116: Critical Care Medicine | I116: Six anesthetized paralyzed cats with normal lungs were ventilated by high-frequency chest wall compression (HFCWC) at 5 Hz using a single-chamber circumferential cuff enclosing the thorax from the axillae to the xiphisternum. PaCO2 during HFCWC + PEEP (3 cm H2O) was significantly (p less than .0005) lower compared with conventional mechanical ventilation (CMV). End-expiratory lung volume (VL) during HFCWC + PEEP was significantly (p less than .001) lower than VL during CMV + PEEP but was higher than VL during CMV without PEEP. After the cats' lungs were stiffened by repeated saline lavage, CMV + PEEP at a mean airway pressure (Paw) of 10 cm H2O was compared with HFCWC + continuous positive airway pressure (CPAP) at an equal or lower Paw. A significant decrease in PaCO2 (p less than .02) during HFCWC occurred but no significant differences were observed in PaO2, VL, or compliance. Arterial BP and cardiac output were similar between CMV + PEEP and HFCWC + CPAP. In cats with normal lungs, VL can be maintained by applying CPAP during HFCWC, and in those with injured lungs, HFCWC + CPAP produces comparable gas exchange at a Paw equal to or lower than that used during CMV + PEEP. | J116: Asli | K116: Terverifikasi
A117: 113 | B117: S0115 | C117: PubMed | D117: 10.1007/s00380-024-02429-y | E117: Kitada S, Kawada Y, Nakasuka K, Mizoguchi T, Yamamoto J, Yokoi M, Ito T, Goto T, Kikuchi S, Seo Y | F117: Elevated arginine vasopressin levels surrogate acute lung injury in acute decompensated heart failure | G117: 2024 | H117: Heart and Vessels | I117: Activated arginine vasopressin (AVP) pathway worsens congestion in heart failure (HF), but its potential to relieve pulmonary congestion is also reported. The pathophysiological role and prognostic utility of AVP elevation in acute decompensated HF (ADHF) are poorly understood. We prospectively enrolled 52 hospitalized patients for ADHF to investigate the association between acute lung injury (ALI) in ADHF and AVP levels on admission. ALI was defined as respiratory failure leading to death, or requiring a respirator or a more than 12-h non-invasive intermittent positive pressure ventilation (NIPPV) support. In addition, we investigated the prognostic value of AVP levels on admission for cardiovascular death or recurrence of ADHF after discharge. ALI was documented in 7 patients (13.5%) during a median hospital stay of 14 days. And the patients with ALI demonstrated significantly higher AVP levels than those without (32.5 ± 21.6 vs. 6.4 ± 8.7 pg/ml, p = 0.018). Besides, the patients with ALI demonstrated significantly higher heart rates (HR) and lower E/e' on admission (HR: 127 ± 24 vs. 97 ± 28 bpm; E/e': 10.6 ± 3.7 vs. 17.4 ± 6.2, all p < 0.05, respectively). Of note, significant hemodilution assessed by hemoglobin and hematocrit values were observed in the patients with ALI 48 h after admission. A receiver operating characteristic curve analysis showed that higher than 7.2 pg/ml surrogate ALI in ADHF (AUC: 0.897, p = 0.001, Sensitivity: 85.7%, and Specificity: 77.8%). In contrast, increased AVP levels on admission could not predict cardiovascular events after discharge. Elevated AVP levels on admission are associated with ALI in ADHF but not cardiovascular events after discharge. | J117: Asli | K117: Terverifikasi
A118: 114 | B118: S2358 | C118: PubMed | D118: 10.1097/01.ccm.0000168042.59035.d8 | E118: Burns KEA, Sinuff T, Adhikari NKJ, Meade MO, Heels-Ansdell D, Martin CM, Cook DJ | F118: Bilevel noninvasive positive pressure ventilation for acute respiratory failure: Survey of Ontario practice* | G118: 2005 | H118: Critical Care Medicine | I118: OBJECTIVE: Noninvasive positive pressure ventilation (NIPPV) is commonly used in acute respiratory failure but is often applied outside evidence-based indications, particularly in low- and middle-income countries. Our objective is to assess the appropriateness of NIPPV use among internal medicine patients at a tertiary hospital in Pakistan. Appropriate use was defined as Type 1 or Type 2 respiratory failure, cardiogenic pulmonary edema, or chest wall/neuromuscular disease. Inappropriate use was defined as NIPPV applied outside standard indications. RESULTS: We conducted a cross-sectional study on 4369 patients who received NIPPV between 2019 and 2020 in the Internal Medicine unit at the Aga Khan University Hospital, Karachi. The mean age was 62.7 years, and 52.4% were male. Overall, 60.5% received NIPPV without documented respiratory failure, 21.5% had Type 1, and 18% had Type 2 failure. Metabolic acidosis accounted for 19.6% of inappropriate cases. Among Type 1 failure, pneumonia (43.1%), pulmonary edema (35.3%), and COPD (6.2%) were most common; in Type 2 failure, pulmonary edema (37.7%), pneumonia (25.8%), and COPD (15.1%) predominated. NIPPV was appropriately used in COPD and acute cardiogenic pulmonary edema but frequently applied outside evidence-based indications, particularly for metabolic acidosis. Structured protocols and research are needed on NIPPV use in LMICs. | J118: Asli | K118: Terverifikasi
A119: 115 | B119: S0400 | C119: PubMed | D119: 10.1136/pmj.78.919.257 | E119: Khurshid I, Anderson LC | F119: Non-infectious pulmonary complications after bone marrow transplantation | G119: 2002 | H119: Postgraduate Medical Journal | I119: Bone marrow transplantation (BMT) is a successful and recognised treatment option for patients with a number of haematological and non-haematological malignant and non-malignant conditions. Pulmonary complications both infectious and non-infectious are common after BMT. Multiple factors are thought to contribute to pulmonary complications, including the type and duration of immunological defects produced by the underlying disease and treatment, the development of graft-versus-host disease (GVHD), and the conditioning regimens employed. These complications are classified as early or late, depending on whether they occur before or after 100 days from transplantation. Early non-infectious pulmonary complications typically include pulmonary oedema, upper airway complications, diffuse alveolar haemorrhage, cytolytic thrombi, and pleural effusion. Bronchiolitis obliterans, veno-occlusive disease, and secondary malignancies occur late after BMT. Idiopathic pneumonia syndrome, GVHD, and radiation induced lung injury can occur in early or late period after BMT. | J119: Asli | K119: Terverifikasi
A120: 116 | B120: S2309 | C120: PubMed | D120: 10.1007/s11845-016-1456-0 | E120: Mac Donncha C, Cummins N, Hennelly D, Hannigan A, Ryan D | F120: An observational study of the utility of continuous positive airway pressure ventilation for appropriate candidates in prehospital care in the Midwest region | G120: 2016 | H120: Irish Journal of Medical Science (1971 -) | I120: Emergency medical services (EMS) practitioners in Ireland have been recently licensed to use continuous positive airway pressure (CPAP) ventilation for patients with pulmonary oedema. Both the British Thoracic Society and the Canadian Medical Association advocate the use of CPAP in hospital for patients with severe exacerbations of pulmonary oedema. The aim of this study was to identify prehospital patients in the Midwest, over a 6-month period, which could potentially benefit from CPAP if it were available in the National Ambulance Service. Potential CPAP patients were identified in the Advanced Paramedic Clinical Activity Study (APCAS) database and then followed up in the receiving hospital emergency department (ED) and medical records. Prior to this study, Irish guidance for prehospital use of CPAP did not exist and therefore the database was interrogated using a Toronto EMS Medical Directive. Descriptive analysis was conducted in Microsoft Excel and SPSS. Emergency AS1 calls (999/112) were assessed (n = 1369) and 141 patients (10.3, 95 % confidence interval 8.9-12.1 %) were identified as potential candidates for prehospital CPAP. Further investigation of ED records for 63 potential candidates found 36.5 % (95 % confidence interval 26-49 %) met the Toronto EMS criteria for CPAP. This study suggests that a suitable patient cohort for CPAP exists in the prehospital environment and highlights the need for a prospective study of CPAP use on these patients. | J120: Asli | K120: Terverifikasi
A121: 117 | B121: S0638 | C121: PubMed | D121: 10.1183/09031936.03.00039503 | E121: Saatci E, Miller DM, Stell IM, Lee KC, Moxham J | F121: Dynamic dead space in face masks used with noninvasive ventilators: a lung model study | G121: 2003 | H121: European Respiratory Journal | I121: The aim of this study was to determine what the influence of different designs of face masks and different noninvasive ventilator modes would be upon total dynamic dead space. Using a spontaneous breathing model, total dynamic dead space was measured when using 19 commercially available face masks and a range of ventilators in various ventilation modes. Total dynamic dead space during spontaneous ventilation was increased above physiological dead space from 32% to 42% of tidal volume by using face masks. The use of noninvasive ventilation modes such as bilevel and continuous positive airway pressure, with continuous pressure throughout the expiratory phase, reduced total dynamic dead space to approach physiological dead space with most face masks. Pressure assist and pressure support ventilation decreased total dynamic dead space to a lesser degree, from 42% to 39% of tidal volume. Face masks with expiratory ports over the nasal bridge resulted in beneficial flow characteristics within the face mask and nasal cavity, so as to decrease total dynamic dead space to less than physiological dead space from 42% to 28.5% of tidal volume. Exhaust ports over the nasal bridge in face masks effect important decreases in dynamic dead space provided positive pressure throughout the expiratory phase is used. | J121: Asli | K121: Terverifikasi
A122: 118 | B122: S1448 | C122: PubMed | D122: 10.1177/1479972313493795 | E122: Porhomayon J, Papadakos P, Nader ND, El-Solh AA | F122: Weaning failure: My heart is not up to it | G122: 2013 | H122: Chronic Respiratory Disease | I122: Weaning patients from mechanical ventilation has been compared to a cardiac stress test. Weaning failure (WF) from a cardiac origin can be common in patients with limited cardiac reserve. Diuretic and vasodilator therapies are indicated for WF due to excessive preload, afterload, or myocardial ischemia. Alteration in intrathoracic pressure and lung volumes may also impact weaning process in a patient with poor cardiac function. Noninvasive ventilation decreases cardiac stress load and should be utilized in weaning patients with poor cardiac reserves. In fact, positive pressure therapy is now the standard of care for treating a patient with acute pulmonary edema and to decrease afterload (Frazier et al. Biol Res Nurs 2000; 1(4): 253–264; Pinsky MR. Chest 2005; 128(5 Suppl 2): 592S–597S.). Recently, biomarkers and echocardiography have been utilized to assess weaning success during spontaneous breathing trials. In this article, we describe the physiological alterations in cardiac and pulmonary systems during the weaning process and its impact on weaning outcome. | J122: Asli | K122: Terverifikasi
A123: 119 | B123: S2393 | C123: PubMed | D123: 10.1161/01.res.0000043825.01705.1b | E123: Mann DL | F123: Inflammatory Mediators and the Failing Heart | G123: 2002 | H123: Circulation Research | I123: Recent studies have identified the importance of proinflammatory mediators in the development and progression of heart failure. The growing appreciation of the pathophysiological consequences of sustained expression of proinflammatory mediators in preclinical and clinical heart failure models culminated in a series of multicenter clinical trials that used “targeted” approaches to neutralize tumor necrosis factor in patients with moderate to advanced heart failure. However, these targeted approaches have resulted in worsening heart failure, thereby raising a number of important questions about what role, if any, proinflammatory cytokines play in the pathogenesis of heart failure. This review will summarize the tremendous growth of knowledge that has taken place in this field, with a focus on what we have learned from the negative clinical trials, as well as the potential direction of future research in this area. | J123: Asli | K123: Terverifikasi
A124: 120 | B124: S0564 | C124: PubMed | D124: 10.1177/000331978803900302 | E124: Bier AJ, Eichacker PQ, Sinoway LI, Terribile SM, Strom JA, Keefe DL | F124: Acute Cardiogenic Pulmonary Edema: Clinical and Noninvasive Evaluation | G124: 1988 | H124: Angiology | I124: Left ventricular echocardiograms performed within ninety-six hours of ad mission were prospectively correlated with the clinical course in 87 consecutive patients admitted with acute pulmonary edema. Patients were stratified into four groups based on their two-dimensional echocardiogram: hyperdynamic, normal, mildly reduced, and severely reduced. Echocardiographic estimates of left ventricular function were compared with their ejection fraction measured by the gated radioisotope technique. The authors found that 48% of the patients were either normal or hyperdynamic (38% and 10% respectively). Patients in these two groups had a greater incidence of left ventricular hypertrophy (wall thickness &gt; 13mm) (66% vs 39%, p &lt; .05), hypertension on admission (BP &gt; 160/100) (66% vs 41%, p=.05), and smaller end-diastolic dimension (p &lt; .05) than those with decreased left ventricualr function. The authors con clude that echocardiography is a good screening test of left ventricular function in patients presenting with pulmonary edema. Patients with normal or in creased left ventricular systolic function should be evaluated for correctable or treatable causes of acute pulmonary edema. | J124: Asli | K124: Terverifikasi
... A153: 149 | B153: S0848 | C153: PubMed | D153: 10.1152/jappl.1981.51.5.1287 | E153: Slutsky AS | F153: Gas mixing by cardiogenic oscillations: a theoretical quantitative analysis | G153: 1981 | H153: Journal of Applied Physiology | I153: A quantitative theoretical model of the enhanced gas mixing secondary to cardiogenic oscillations is presented based on the concept of augmented gas transport within the tracheobronchial tree (Science 209: 609, 1980). The model assumes “well-mixed” flow in the upper airways with the enhanced mixing described by Deff = Dmol + K . ud, where Deff is the effective diffusivity; Dmol, the molecular diffusivity: K, a constant; u, the root-mean-square flow; and d, the airway diameter. In the smaller airways on analysis based on Taylor laminar dispersion is used described by Deff = Dmol + (1/192) (ud)2/Dmol. The model predicts that, in dogs, cardiogenic oscillations should enhance gas mixing about 10-fold depending on the flow rates generated by the heart. Other predictions are that the augmentation of gas mixing should be greater 1) at lower lung volumes, 2) with sulfur hexafluoride vs. helium or air, 3) after peripheral airway dilation, and 4) after central airways constriction. Theoretical predictions are very close to published experimental results where available. This model should help in the development of mathematical models of gas mixing within the lungs that will include the contribution of cardiogenic oscillations. | J153: Asli | K153: Terverifikasi
A154: 150 | B154: S0021 | C154: PubMed | D154: 10.21203/rs.2.123/v1 | E154: Freund Y, Gorlick J, Cachanado M, Salhi S, Lemaitre V, Simon T, Mebazaa A | F154: Early and comprehensive care bundle in elderly for acute heart failure in the emergency department: study protocol of The ELISABETH stepped wedge cluster randomized trial | G154: 2018 | I154: Background: Acute heart failure (AHF) is one of the most common diagnoses for elderly patients in the emergency department (ED), with an admission rate higher than 80% and 1-month mortality around 10%. The European guidelines for the management of AHF are based on moderate levels of evidence, due to the lack of randomized controlled trials and the scarce evidence of any clinical added value of a specific treatment to improve outcomes. Recent reports suggest that the very early administration of full recommended therapy may decrease mortality. However, several studies highlighted that elderly patients often received suboptimal treatment. Our hypothesis is that an early care bundle that comprises early and comprehensive management of symptoms, along with prompt detection and treatment of precipitating factors should improve AHF outcome in elderly patients. Method/design: ELISABETH is a stepped-wedge, controlled cluster randomized, clinical trial in 15 emergency departments in France recruiting all patients aged 75 years and older with a diagnosis of AHF. The tested intervention is a care bundle with a checklist that mandates detection and early treatment of AHF precipitating factors, early and intensive treatment of congestion with intravenous nitrates boluses, and application of other recommended treatment (low dose diuretics, non-invasive ventilation when indicated, and preventive low molecular weight heparin). Each centre are randomized to the order in which they will switch from “control period” to “intervention period”. All centers begin the trials with the control period for two weeks, then after each two-weeks step a new centre will be in the intervention period. At the end of the trial, all clusters will receive the intervention regimen. The primary outcome is the number of days alive and out of the hospital at 30 days. Discussion: If our hypothesis is confirmed, this trial will strengthen the level of evidence of AHF guidelines and stress the importance of the associated early and comprehensive treatment of precipitating factors. This trial could be the first to report a reduction in short term morbidity and mortality in elderly AHF patients. Registration: NCT03683212, prospectively registered on September 25th 2018 Keywords: Elderly, acute heart failure, emergency department | J154: Asli | K154: Terverifikasi
